#VRML_SIM R2023b utf8

EXTERNPROTO "https://raw.githubusercontent.com/cyberbotics/webots/R2023b/projects/objects/backgrounds/protos/TexturedBackground.proto"
EXTERNPROTO "https://raw.githubusercontent.com/cyberbotics/webots/R2023b/projects/objects/backgrounds/protos/TexturedBackgroundLight.proto"
EXTERNPROTO "https://raw.githubusercontent.com/cyberbotics/webots/R2023b/projects/objects/floors/protos/RectangleArena.proto"

WorldInfo {
}
Viewpoint {
  orientation 0.05912381768338287 -0.019398555830345283 -0.9980621574903235 4.310147535844364
  position 0.550093452913756 -1.5508865347737422 0.40760888579910254
}
TexturedBackground {
}
TexturedBackgroundLight {
}
RectangleArena {
}
Robot {
  children [
    DEF eye2 Solid {
      translation 0.15 0.0005 0.29
      rotation 0 1 0 1.57
      children [
        DEF Eye Shape {
          appearance PBRAppearance {
            baseColor 1 0 0
          }
          geometry Cylinder {
            height 0.01
            radius 0.018
          }
        }
      ]
      name "solid(2)"
    }
    DEF eye1 Solid {
      translation 0.15 -0.05 0.29
      rotation 0 1 0 1.57
      children [
        USE Eye
      ]
      name "solid(3)"
    }
    DEF eye3 Solid {
      translation 0.15 0.05 0.29
      rotation 0 1 0 1.57
      children [
        USE Eye
      ]
      name "solid(4)"
    }
    HingeJoint {
      jointParameters HingeJointParameters {
        anchor 0.13 0.08 0.025
      }
      device [
        RotationalMotor {
          name "motor1"
        }
      ]
      endPoint Solid {
        translation 0.13 0.08 0.025
        rotation 1 0 0 1.57
        children [
          DEF Wheel Shape {
            appearance PBRAppearance {
              baseColor 0 0 0.498039
              roughness 1
              metalness 0
            }
            geometry Cylinder {
              height 0.01
              radius 0.025
            }
          }
        ]
        boundingObject USE Wheel
        physics DEF wheelPhysics Physics {
        }
      }
    }
    DEF BODY Pose {
      translation 0 0 0.17
      children [
        Shape {
          appearance PBRAppearance {
            baseColor 0.180392 0.180392 0.180392
            roughness 1
            metalness 0
          }
          geometry Box {
            size 0.3 0.15 0.3
          }
        }
      ]
    }
    HingeJoint {
      jointParameters HingeJointParameters {
        anchor 0.03 -0.08 0.025
      }
      device [
        RotationalMotor {
          name "motor2"
        }
      ]
      endPoint Solid {
        translation 0.13 -0.08 0.025
        rotation 1 0 0 1.57
        children [
          USE Wheel
        ]
        name "solid(1)"
        boundingObject USE Wheel
        physics USE wheelPhysics
      }
    }
  ]
  boundingObject USE BODY
  physics Physics {
  }
}
